Workbook

Sheet Dashboard
B2: Thomas Severn — Financial Plan
B3: West Carr & Harvey · commenced 24 Aug 2026 · built Aug 2026
B5: NET INCOME / MONTH (full-time) | D5: MONTHLY SURPLUS (2027, full-time)
B6: ='Income & Tax'!C14 -> 4215.5833 | D6: ='Income & Tax'!C14-Budget!C15 -> 2401.7432
B7: after tax, Medicare, $0 HECS | D7: what you can save each month
B9: EMERGENCY FUND TARGET | D9: NET DEPOSIT GOAL
B10: =Inputs!$B$43 -> 5000 | D10: =Inputs!$B$38*Inputs!$B$39+Inputs!$B$41-Inputs!$B$40 -> 27000
B11: build this first — then pivot to deposit | D11: 5% deposit + costs − FHOG
B13: DEPOSIT SAVED BY END 2029 | D13: FHSS TAX SAVING (per $15k yr)
B14: ='Savings Plan'!J44 -> 94786.628 | D14: =(0.32-0.15)*Inputs!$B$47 -> 2550
B15: on current plan, cash only | D15: route savings via super
B17: What changed / what matters
B18: • HECS: you pay $0 compulsory repayments — your ~$60.7k salary is under the new $69,528 threshold.
B19: • Scheme: the Regional guarantee merged into the national 5% Deposit Scheme (1 Oct 2025) — no income caps, Geelong $950k cap.
B20: • Your deposit will be ready well before your borrowing capacity is — 2029 timing hinges on income growth + your partner's income.
B21: • Living at home = a very high savings rate. Emergency fund ($5k) fills in ~2 months, then everything goes to the deposit.
B23: Tabs: Income & Tax · Budget · Savings Plan (month-by-month) · FHSS · House & Scheme · Inputs (edit yellow cells)
B24: General information to help you plan, prepared from the figures you gave me — not personal financial, tax or credit advice. Confirm specifics with your accountant / a licensed adviser before acting.

Sheet Income & Tax
A1: Income & Tax — new WCH salary (2026-27 rules)
A3: Annualised figures | B3: Part-time | C3: Full-time | D3: Notes
A4: Salary package (incl. super) | B4: =Inputs!$B$4*Inputs!$B$6 -> 54400 | C4: =Inputs!$B$4 -> 68000
A5: Cash salary (taxable income) | B5: =B4/(1+Inputs!$B$5) -> 48571.429 | C5: =C4/(1+Inputs!$B$5) -> 60714.286 | D5: This is what's taxed
A6: Employer super (to UniSuper) | B6: =B4-B5 -> 5828.5714 | C6: =C4-C5 -> 7285.7143 | D6: Grows your super, incl. FHSS room
A8: Income tax (2025-26 scale) | B8: =0.16*MAX(0,MIN(B5,45000)-18200)+0.3*MAX(0,MIN(B5,135000)-45000)+0.37*MAX(0,MIN(B5,190000)-135000)+0.45*MAX(0,B5-190000) -> 5359.4286 | C8: =0.16*MAX(0,MIN(C5,45000)-18200)+0.3*MAX(0,MIN(C5,135000)-45000)+0.37*MAX(0,MIN(C5,190000)-135000)+0.45*MAX(0,C5-190000) -> 9002.2857 | D8: Nil to $18,200; 16%; 30%; 37%; 45%
A9: less Low Income Tax Offset (LITO) | B9: =-1*IF(B5<=37500,700,IF(B5<=45000,700-(B5-37500)*0.05,IF(B5<66667,325-(B5-45000)*0.015,0))) -> -271.42857 | C9: =-1*IF(C5<=37500,700,IF(C5<=45000,700-(C5-37500)*0.05,IF(C5<66667,325-(C5-45000)*0.015,0))) -> -89.285714 | D9: Reduces tax at low incomes
A10: Medicare levy (2%) | B10: =0.02*B5 -> 971.42857 | C10: =0.02*C5 -> 1214.2857 | D10: 2% of taxable income
A11: HECS-HELP compulsory repayment | B11: =0.15*MAX(0,B5-Inputs!$B$46) -> 0 | C11: =0.15*MAX(0,C5-Inputs!$B$46) -> 0 | D11: 15c per $ above $69,528 — you're UNDER it
A12: Total tax + levies | B12: =MAX(0,B8+B9)+B10+B11 -> 6059.4286 | C12: =MAX(0,C8+C9)+C10+C11 -> 10127.286
A13: NET annual income | B13: =B5-B12 -> 42512 | C13: =C5-C12 -> 50587
A14: NET per month | B14: =B13/12 -> 3542.6667 | C14: =C13/12 -> 4215.5833
A15: NET per fortnight | B15: =B13/26 -> 1635.0769 | C15: =C13/26 -> 1945.6538
A17: Phases: Part-time (4 days, Mon–Thu) from 24 Aug 2026 → Full-time (5 days) from 19 Oct 2026.
A18: HECS = $0 because your ~$60.7k cash salary is below the $69,528 threshold. It only starts once your income grows past that.

Sheet Budget
A1: Monthly Budget
A3: Expense (monthly) | B3: 2026 (now) | C3: 2027+ | D3: Basis
A4: Board (living at parents') | B4: 0 | C4: =Inputs!$B$33*52/12 -> 433.33333 | D4: $0 now → $100/wk from 2027
A5: Own groceries / food | B5: =Inputs!$B$32*52/12 -> 476.66667 | C5: =Inputs!$B$32*52/12 -> 476.66667 | D5: Your figure ÷ set weekly
A6: Fuel | B6: =Inputs!$B$21*52/12 -> 238.33333 | C6: =Inputs!$B$21*52/12 -> 238.33333 | D6: Weekly × 52 ÷ 12
A7: Car insurance | B7: =Inputs!$B$22/12 -> 58.345 | C7: =Inputs!$B$22/12 -> 58.345 | D7: Annual ÷ 12
A8: Car registration | B8: =Inputs!$B$23/12 -> 68.716667 | C8: =Inputs!$B$23/12 -> 68.716667 | D8: Annual ÷ 12
A9: Gym | B9: =Inputs!$B$24*26/12 -> 82.116667 | C9: =Inputs!$B$24*26/12 -> 82.116667 | D9: Fortnightly × 26 ÷ 12
A10: Basketball (rego + games) | B10: =(Inputs!$B$25*Inputs!$B$26+Inputs!$B$27*Inputs!$B$28)/12 -> 58.536667 | C10: =(Inputs!$B$25*Inputs!$B$26+Inputs!$B$27*Inputs!$B$28)/12 -> 58.536667 | D10: Seasons + games ÷ 12
A11: Private health insurance | B11: 0 | C11: =Inputs!$B$34 -> 130 | D11: $0 now → $130/mo from 2027
A12: Claude Pro | B12: =Inputs!$B$29 -> 34 | C12: =Inputs!$B$29 -> 34 | D12: Monthly
A13: iRacing | B13: =Inputs!$B$30*Inputs!$B$31/3 -> 17.12513 | C13: =Inputs!$B$30*Inputs!$B$31/3 -> 17.12513 | D13: US$/qtr x FX ÷ 3
A14: Fun money (nights out, sink fund) | B14: =Inputs!$B$35*52/12 -> 216.66667 | C14: =Inputs!$B$35*52/12 -> 216.66667 | D14: Weekly x 52 ÷ 12
A15: TOTAL monthly expenses | B15: =SUM(B4:B14) -> 1250.5068 | C15: =SUM(C4:C14) -> 1813.8401
A17: Net income per month (full-time) | B17: ='Income & Tax'!C14 -> 4215.5833 | C17: ='Income & Tax'!C14 -> 4215.5833
A18: less total expenses | B18: =-B15 -> -1250.5068 | C18: =-C15 -> -1813.8401
A19: MONTHLY SURPLUS (full-time) | B19: =B17+B18 -> 2965.0765 | C19: =C17+C18 -> 2401.7432
A21: Living at home keeps your cost base tiny — that surplus is the engine of the whole plan.

Sheet Savings Plan
A1: Savings Plan — emergency fund first, then house deposit
A3: Month | B3: Phase | C3: Net income | D3: Expenses | E3: Surplus | F3: Available | G3: → Emerg. | H3: Emerg. bal | I3: → Deposit | J3: Deposit bal
A4: Opening | H4: 0 | I4: (ANZ Plus →) | J4: =Inputs!$B$10 -> 3000
A5: 46266 | B5: PT | C5: ='Income & Tax'!$B$14 -> 3542.6667 | D5: =Budget!$B$15 -> 1250.5068 | E5: =C5-D5 -> 2292.1599 | F5: =E5-Inputs!$B$12 -> 2101.5599 | G5: =MAX(0,MIN(F5,Inputs!$B$43-H4)) -> 2101.5599 | H5: =H4+G5 -> 2101.5599 | I5: =F5-G5 -> 0 | J5: =J4+I5 -> 3000
A6: 46296 | B6: PT | C6: ='Income & Tax'!$B$14 -> 3542.6667 | D6: =Budget!$B$15 -> 1250.5068 | E6: =C6-D6 -> 2292.1599 | F6: =E6 -> 2292.1599 | G6: =MAX(0,MIN(F6,Inputs!$B$43-H5)) -> 2292.1599 | H6: =H5+G6 -> 4393.7197 | I6: =F6-G6 -> 0 | J6: =J5+I6 -> 3000
A7: 46327 | B7: FT | C7: ='Income & Tax'!$C$14 -> 4215.5833 | D7: =Budget!$B$15 -> 1250.5068 | E7: =C7-D7 -> 2965.0765 | F7: =E7 -> 2965.0765 | G7: =MAX(0,MIN(F7,Inputs!$B$43-H6)) -> 606.28026 | H7: =H6+G7 -> 5000 | I7: =F7-G7 -> 2358.7963 | J7: =J6+I7 -> 5358.7963
A8: 46357 | B8: FT | C8: ='Income & Tax'!$C$14 -> 4215.5833 | D8: =Budget!$B$15 -> 1250.5068 | E8: =C8-D8 -> 2965.0765 | F8: =E8 -> 2965.0765 | G8: =MAX(0,MIN(F8,Inputs!$B$43-H7)) -> 0 | H8: =H7+G8 -> 5000 | I8: =F8-G8 -> 2965.0765 | J8: =J7+I8 -> 8323.8728
A9: 46388 | B9: FT | C9: ='Income & Tax'!$C$14 -> 4215.5833 | D9: =Budget!$C$15 -> 1813.8401 | E9: =C9-D9 -> 2401.7432 | F9: =E9 -> 2401.7432 | G9: =MAX(0,MIN(F9,Inputs!$B$43-H8)) -> 0 | H9: =H8+G9 -> 5000 | I9: =F9-G9 -> 2401.7432 | J9: =J8+I9 -> 10725.616
A10: 46419 | B10: FT | C10: ='Income & Tax'!$C$14 -> 4215.5833 | D10: =Budget!$C$15 -> 1813.8401 | E10: =C10-D10 -> 2401.7432 | F10: =E10 -> 2401.7432 | G10: =MAX(0,MIN(F10,Inputs!$B$43-H9)) -> 0 | H10: =H9+G10 -> 5000 | I10: =F10-G10 -> 2401.7432 | J10: =J9+I10 -> 13127.359
A11: 46447 | B11: FT | C11: ='Income & Tax'!$C$14 -> 4215.5833 | D11: =Budget!$C$15 -> 1813.8401 | E11: =C11-D11 -> 2401.7432 | F11: =E11 -> 2401.7432 | G11: =MAX(0,MIN(F11,Inputs!$B$43-H10)) -> 0 | H11: =H10+G11 -> 5000 | I11: =F11-G11 -> 2401.7432 | J11: =J10+I11 -> 15529.102
A12: 46478 | B12: FT | C12: ='Income & Tax'!$C$14 -> 4215.5833 | D12: =Budget!$C$15 -> 1813.8401 | E12: =C12-D12 -> 2401.7432 | F12: =E12 -> 2401.7432 | G12: =MAX(0,MIN(F12,Inputs!$B$43-H11)) -> 0 | H12: =H11+G12 -> 5000 | I12: =F12-G12 -> 2401.7432 | J12: =J11+I12 -> 17930.846
A13: 46508 | B13: FT | C13: ='Income & Tax'!$C$14 -> 4215.5833 | D13: =Budget!$C$15 -> 1813.8401 | E13: =C13-D13 -> 2401.7432 | F13: =E13 -> 2401.7432 | G13: =MAX(0,MIN(F13,Inputs!$B$43-H12)) -> 0 | H13: =H12+G13 -> 5000 | I13: =F13-G13 -> 2401.7432 | J13: =J12+I13 -> 20332.589
A14: 46539 | B14: FT | C14: ='Income & Tax'!$C$14 -> 4215.5833 | D14: =Budget!$C$15 -> 1813.8401 | E14: =C14-D14 -> 2401.7432 | F14: =E14 -> 2401.7432 | G14: =MAX(0,MIN(F14,Inputs!$B$43-H13)) -> 0 | H14: =H13+G14 -> 5000 | I14: =F14-G14 -> 2401.7432 | J14: =J13+I14 -> 22734.332
A15: 46569 | B15: FT | C15: ='Income & Tax'!$C$14 -> 4215.5833 | D15: =Budget!$C$15 -> 1813.8401 | E15: =C15-D15 -> 2401.7432 | F15: =E15 -> 2401.7432 | G15: =MAX(0,MIN(F15,Inputs!$B$43-H14)) -> 0 | H15: =H14+G15 -> 5000 | I15: =F15-G15 -> 2401.7432 | J15: =J14+I15 -> 25136.075
A16: 46600 | B16: FT | C16: ='Income & Tax'!$C$14 -> 4215.5833 | D16: =Budget!$C$15 -> 1813.8401 | E16: =C16-D16 -> 2401.7432 | F16: =E16 -> 2401.7432 | G16: =MAX(0,MIN(F16,Inputs!$B$43-H15)) -> 0 | H16: =H15+G16 -> 5000 | I16: =F16-G16 -> 2401.7432 | J16: =J15+I16 -> 27537.818
A17: 46631 | B17: FT | C17: ='Income & Tax'!$C$14 -> 4215.5833 | D17: =Budget!$C$15 -> 1813.8401 | E17: =C17-D17 -> 2401.7432 | F17: =E17 -> 2401.7432 | G17: =MAX(0,MIN(F17,Inputs!$B$43-H16)) -> 0 | H17: =H16+G17 -> 5000 | I17: =F17-G17 -> 2401.7432 | J17: =J16+I17 -> 29939.562
A18: 46661 | B18: FT | C18: ='Income & Tax'!$C$14 -> 4215.5833 | D18: =Budget!$C$15 -> 1813.8401 | E18: =C18-D18 -> 2401.7432 | F18: =E18 -> 2401.7432 | G18: =MAX(0,MIN(F18,Inputs!$B$43-H17)) -> 0 | H18: =H17+G18 -> 5000 | I18: =F18-G18 -> 2401.7432 | J18: =J17+I18 -> 32341.305
A19: 46692 | B19: FT | C19: ='Income & Tax'!$C$14 -> 4215.5833 | D19: =Budget!$C$15 -> 1813.8401 | E19: =C19-D19 -> 2401.7432 | F19: =E19 -> 2401.7432 | G19: =MAX(0,MIN(F19,Inputs!$B$43-H18)) -> 0 | H19: =H18+G19 -> 5000 | I19: =F19-G19 -> 2401.7432 | J19: =J18+I19 -> 34743.048
A20: 46722 | B20: FT | C20: ='Income & Tax'!$C$14 -> 4215.5833 | D20: =Budget!$C$15 -> 1813.8401 | E20: =C20-D20 -> 2401.7432 | F20: =E20 -> 2401.7432 | G20: =MAX(0,MIN(F20,Inputs!$B$43-H19)) -> 0 | H20: =H19+G20 -> 5000 | I20: =F20-G20 -> 2401.7432 | J20: =J19+I20 -> 37144.791
... A44: 47453 | B44: FT | C44: ='Income & Tax'!$C$14 -> 4215.5833 | D44: =Budget!$C$15 -> 1813.8401 | E44: =C44-D44 -> 2401.7432 | F44: =E44 -> 2401.7432 | G44: =MAX(0,MIN(F44,Inputs!$B$43-H43)) -> 0 | H44: =H43+G44 -> 5000 | I44: =F44-G44 -> 2401.7432 | J44: =J43+I44 -> 94786.628
A46: Deposit saved by target year end: | D46: =J44 -> 94786.628
A47: Cruise (~$3,100) is paid from your ring-fenced holiday account, so it doesn't touch this savings flow.
A48: Shaded rows = January (board $100/wk + private health $130/mo begin, so surplus steps down).

Sheet Investments
A1: Investments & Net Position
A3: Share portfolio — CMC Markets (a/c 677756)
A5: Code | B5: Company | C5: Units | D5: Last price (AUD) | E5: Value (AUD) | F5: Weight | G5: Est. gross div/yr
A6: AGL | B6: AGL Energy | C6: 60 | D6: 8.71 | E6: =C6*D6 -> 522.6 | F6: =E6/$E$11 -> 0.14735655
A7: ANZ | B7: ANZ Group Holdings | C7: 19 | D7: 38.04 | E7: =C7*D7 -> 722.76 | F7: =E7/$E$11 -> 0.20379529
A8: LTR | B8: Liontown Resources | C8: 629 | D8: 1.23 | E8: =C8*D8 -> 773.67 | F8: =E8/$E$11 -> 0.21815029
A9: ORG | B9: Origin Energy | C9: 76 | D9: 11.86 | E9: =C9*D9 -> 901.36 | F9: =E9/$E$11 -> 0.2541548
A10: S32 | B10: South32 | C10: 127 | D10: 4.93 | E10: =C10*D10 -> 626.11 | F10: =E10/$E$11 -> 0.17654307
A11: TOTAL | C11: =SUM(C6:C10) -> 911 | E11: =SUM(E6:E10) -> 3546.5 | F11: 1 | G11: =SUM(G6:G10) -> 0
A13: Prices are the delayed figures from your screenshot — update the BLUE units/price as your holdings change. Yellow column: add each stock's gross dividend/yr (incl. franking) to capture it as income.
A15: Net position (simple net worth)
A16: Share portfolio | E16: =E11 -> 3546.5
A17: Super (UniSuper) | E17: =Inputs!$B$14 -> 19790.73
A18: Cash — house deposit (ANZ Plus) | E18: =Inputs!$B$10 -> 3000
A19: Cash — holiday account (cruise) | E19: =Inputs!$B$11 -> 3100
A20: Cash — everyday | E20: =Inputs!$B$9 -> 0
A21: Total assets | E21: =SUM(E16:E20) -> 29437.23
A23: less Credit card | E23: =-Inputs!$B$12 -> -190.6
A24: less HECS-HELP debt | E24: =-Inputs!$B$17 -> -45182.77
A25: NET POSITION | E25: =E21+SUM(E23:E24) -> -15936.14
A27: HECS drags the net figure negative today — normal for a new grad, and it's the cheapest debt you'll ever hold (2.8% indexation, $0 compulsory repayments at your income).

Sheet FHSS
A1: First Home Super Saver (FHSS) strategy
A3: Route some deposit savings through super: contributions taxed at 15% instead of your 32% marginal rate,
A4: then released (plus deemed earnings) when you buy. You've used $8k of your $50k lifetime cap.
A6: Lifetime cap position
A7: FHSS lifetime cap | B7: =Inputs!$B$48 -> 50000 | C7: Max releasable across all years
A8: Already contributed (voluntary) | B8: =Inputs!$B$49 -> 8000 | C8: Last FY — $7k concessional + $1k non-conc.
A9: Remaining lifetime headroom | B9: =Inputs!$B$48-Inputs!$B$49 -> 42000 | C9: Room still to use
A11: If you contribute the annual max this year
A12: Annual voluntary cap | B12: =Inputs!$B$47 -> 15000 | C12: Max counted per financial year
A13: as concessional (salary sacrifice / deductible) | B13: =Inputs!$B$47 -> 15000 | C13: Within your $30k concessional cap
A14: Tax on the way IN (15%) | B14: =-0.15*Inputs!$B$47 -> -2250 | C14: vs 32% if taken as normal pay
A15: Tax you'd have paid at 32% marginal | B15: =-0.32*Inputs!$B$47 -> -4800 | C15: 30% + 2% Medicare
A16: → Tax SAVED this year | B16: =(0.32-0.15)*Inputs!$B$47 -> 2550 | C16: The FHSS advantage
A17: Amount counted toward release (85% of conc.) | B17: =0.85*Inputs!$B$47 -> 12750 | C17: Only 85% of concessional counts
A19: Watch-outs
A20: • Salary-sacrificed super counts toward your HECS 'repayment income' — but even adding $15k keeps you near/under the $69,528 line, so still ~$0 HECS.
A21: • Money is locked in super until you request an ATO release for your first home — don't route your $5k emergency fund through it.
A22: • Request the FHSS determination BEFORE you sign a contract, and release within 90 days of signing.
A23: • Deemed earnings (not your fund's actual return) are added on release, using the ATO shortfall-interest rate.

Sheet House & Scheme
A1: House deposit & the 5% Deposit Scheme
A3: Cash needed to buy (2029 target)
A4: House-and-land target | B4: =Inputs!$B$38 -> 680000 | C4: Set your real target on Inputs
A5: Deposit at 5% (no LMI) | B5: =Inputs!$B$38*Inputs!$B$39 -> 34000 | C5: Home Guarantee = 5% deposit
A6: plus buying costs | B6: =Inputs!$B$41 -> 3000 | C6: Conveyancing, inspections, loan fees
A7: less First Home Owner Grant | B7: =-Inputs!$B$40 -> -10000 | C7: VIC new-build grant (under $750k)
A8: NET CASH TO SAVE | B8: =Inputs!$B$38*Inputs!$B$39+Inputs!$B$41-Inputs!$B$40 -> 27000 | C8: Your real deposit goal
A10: When you'll have it
A11: Deposit already saved (ANZ Plus) | B11: =Inputs!$B$10 -> 3000 | C11: Starting point
A12: Monthly surplus to deposit (2027+, full-time) | B12: ='Income & Tax'!C14-Budget!C15 -> 2401.7432
A13: Months to reach net cash goal (after emerg.) | B13: =ROUNDUP(((Inputs!$B$38*Inputs!$B$39+Inputs!$B$41-Inputs!$B$40)-Inputs!$B$10)/B12,0) -> 10 | C13: Approx, at full-time surplus
A15: The binding constraint isn't the deposit — it's borrowing power
A16: • At a ~$60.7k solo salary, a lender will advance only roughly $340k–$400k. A $680k build needs a ~$646k loan — well beyond solo capacity.
A17: • So your DEPOSIT will be ready years before your BORROWING CAPACITY is. The 2029 timing really depends on: (a) your income growth as you qualify CA, and (b) your partner's income being added to the application.
A18: • Clearing HECS before you apply can lift borrowing capacity (lenders count the repayment) — but it's cheap debt (2.8% indexation), so weigh that against keeping cash liquid.
A19: • This is general information, not personal credit advice — a mortgage broker can model your actual capacity nearer the time.
A21: Scheme facts (verified Aug 2026)
A22: • Regional First Home Guarantee was merged into the national 5% Deposit Scheme on 1 Oct 2025.
A23: • No income caps and no place limits from 1 Oct 2025 — your salary growth won't lock you out.
A24: • Geelong sits at the higher $950k price cap; other regional VIC is $650k. Confirm Armstrong Creek's postcode tier via Housing Australia before signing a build contract.
A25: • For a new build, the cap applies to land + build combined.

Sheet Inputs
A1: Inputs & Assumptions — edit BLUE cells; YELLOW cells need your confirmation
A3: EMPLOYMENT — West Carr & Harvey
A4: Salary package (incl. super), FTE | B4: 68000 | C4: Schedule 1, Item 6 — inclusive of super guarantee
A5: Superannuation guarantee rate | B5: 0.12 | C5: 12% from 1 Jul 2025
A6: Part-time fraction (4 of 5 days) | B6: 0.8 | C6: 30 hrs / 37.5 hrs = 80% until 19 Oct 2026
A8: ACCOUNT BALANCES (opening)
A9: Everyday transaction account | B9: 0 | C9: You confirmed $0 now; final Bowls pay (~$1,110) lands Wed and flows in via the Savings Plan
A10: ANZ Plus — house deposit account | B10: 3000 | C10: Your stated balance
A11: Holiday account (Dec cruise) | B11: 3100 | C11: Ring-fenced; spent on cruise, not deposit
A12: Credit card balance owing | B12: 190.6 | C12: Limit $2,000; clear this first
A13: Share portfolio (CMC) | B13: =Investments!$E$11 -> 3546.5 | C13: Live total from Investments tab
A14: UniSuper balance | B14: 19790.73 | C14: Includes $8,000 FHSS-eligible contributions
A16: DEBTS
A17: HECS-HELP balance | B17: 45182.77 | C17: Already reflects the 20% cut (applied 1 Jun 2025)
A18: Remaining units to add (4 x $2,174) | B18: 8696 | C18: 4 units incl. ASC320; added as you enrol
A20: EXPENSES (as you gave them)
A21: Fuel — per week | B21: 55 | C21: You said $50–60/wk; midpoint used
A22: Car insurance — per year | B22: 700.14 | C22: Paid 11 Apr; renews annually
A23: Car registration — per year | B23: 824.6
A24: Gym — per fortnight | B24: 37.9
A25: Basketball registration — per season | B25: 128.5 | C25: PlayHQ: levy $5.50 + BV $48 + GUB $75
A26: Basketball seasons per year | B26: 2 | C26: Winter + Summer comps
A27: Basketball — per game (Franks Tanks) | B27: 13.92
A28: Basketball games per year | B28: 32 | C28: ~16 games x 2 seasons
A29: Claude Pro — per month | B29: 34 | C29: Your figure: $34 AUD/month
A30: iRacing — per quarter (USD) | B30: 36.3 | C30: Your figure: US$36.30 every 3 months
A31: FX rate USD -> AUD | B31: 1.4153 | C31: Live rate ~Aug 2026; update as needed
A32: Own groceries / food — per week | B32: 110 | C32: Your figure: $110/wk
A33: Board — per week (from Jan 2027) | B33: 100 | C33: $0 in 2026; $100/wk from 2027
A34: Private health — per month (from Jan 2027) | B34: 130 | C34: Starts start of 2027
A35: Fun money — per week (sink fund) | B35: 50 | C35: Set aside weekly; spend on nights out etc.
A37: HOUSE GOAL — Armstrong Creek
A38: House-and-land target (land + build) | B38: 680000 | C38: ESTIMATE for a typical Armstrong Creek package — set your real target
A39: Deposit required (5% Deposit Scheme) | B39: 0.05 | C39: 5% with no LMI under the Home Guarantee
A40: First Home Owner Grant (new build) | B40: 10000 | C40: VIC FHOG for new homes under $750k
A41: Other buying costs | B41: 3000 | C41: Conveyancing, inspections, loan fees (est.)
A42: Target settlement year | B42: 2029 | C42: Your stated goal
A43: Emergency fund target | B43: 5000 | C43: Your stated goal — build this first
A45: TAX / SCHEME SETTINGS (2026-27)
A46: HECS repayment threshold 2026-27 | B46: 69528 | C46: Marginal 15c/$ above this (2026-27)
...
